[2024-05-16T05:27:32.686+0000] {taskinstance.py:1979} INFO - Dependencies all met for dep_context=non-requeueable deps ti=<TaskInstance: data_pipeline.analyze_data manual__2024-05-16T05:26:57.644667+00:00 [queued]>
[2024-05-16T05:27:32.698+0000] {taskinstance.py:1979} INFO - Dependencies all met for dep_context=requeueable deps ti=<TaskInstance: data_pipeline.analyze_data manual__2024-05-16T05:26:57.644667+00:00 [queued]>
[2024-05-16T05:27:32.699+0000] {taskinstance.py:2193} INFO - Starting attempt 1 of 1
[2024-05-16T05:27:32.719+0000] {taskinstance.py:2217} INFO - Executing <Task(PythonOperator): analyze_data> on 2024-05-16 05:26:57.644667+00:00
[2024-05-16T05:27:32.726+0000] {standard_task_runner.py:60} INFO - Started process 7189 to run task
[2024-05-16T05:27:32.730+0000] {standard_task_runner.py:87} INFO - Running: ['***', 'tasks', 'run', 'data_pipeline', 'analyze_data', 'manual__2024-05-16T05:26:57.644667+00:00', '--job-id', '10', '--raw', '--subdir', 'DAGS_FOLDER/pipeline.py', '--cfg-path', '/tmp/tmptg3349jx']
[2024-05-16T05:27:32.732+0000] {standard_task_runner.py:88} INFO - Job 10: Subtask analyze_data
[2024-05-16T05:27:32.798+0000] {task_command.py:423} INFO - Running <TaskInstance: data_pipeline.analyze_data manual__2024-05-16T05:26:57.644667+00:00 [running]> on host e7ad39e8aa43
[2024-05-16T05:27:32.904+0000] {taskinstance.py:2513} INFO - Exporting env vars: AIRFLOW_CTX_DAG_OWNER='***' AIRFLOW_CTX_DAG_ID='data_pipeline' AIRFLOW_CTX_TASK_ID='analyze_data' AIRFLOW_CTX_EXECUTION_DATE='2024-05-16T05:26:57.644667+00:00' AIRFLOW_CTX_TRY_NUMBER='1' AIRFLOW_CTX_DAG_RUN_ID='manual__2024-05-16T05:26:57.644667+00:00'
[2024-05-16T05:27:33.066+0000] {taskinstance.py:2731} ERROR - Task failed with exception
Traceback (most recent call last):
  File "/home/airflow/.local/lib/python3.10/site-packages/pandas/core/indexes/base.py", line 3791, in get_loc
    return self._engine.get_loc(casted_key)
  File "index.pyx", line 152, in pandas._libs.index.IndexEngine.get_loc
  File "index.pyx", line 181, in pandas._libs.index.IndexEngine.get_loc
  File "pandas/_libs/hashtable_class_helper.pxi", line 7080, in pandas._libs.hashtable.PyObjectHashTable.get_item
  File "pandas/_libs/hashtable_class_helper.pxi", line 7088, in pandas._libs.hashtable.PyObjectHashTable.get_item
KeyError: 'price'

The above exception was the direct cause of the following exception:

Traceback (most recent call last):
  File "/home/airflow/.local/lib/python3.10/site-packages/airflow/models/taskinstance.py", line 444, in _execute_task
    result = _execute_callable(context=context, **execute_callable_kwargs)
  File "/home/airflow/.local/lib/python3.10/site-packages/airflow/models/taskinstance.py", line 414, in _execute_callable
    return execute_callable(context=context, **execute_callable_kwargs)
  File "/home/airflow/.local/lib/python3.10/site-packages/airflow/operators/python.py", line 200, in execute
    return_value = self.execute_callable()
  File "/home/airflow/.local/lib/python3.10/site-packages/airflow/operators/python.py", line 217, in execute_callable
    return self.python_callable(*self.op_args, **self.op_kwargs)
  File "/opt/airflow/dags/pipeline.py", line 66, in analyze_data
    average_price = cleaned_properties['price'].mean()
  File "/home/airflow/.local/lib/python3.10/site-packages/pandas/core/frame.py", line 3893, in __getitem__
    indexer = self.columns.get_loc(key)
  File "/home/airflow/.local/lib/python3.10/site-packages/pandas/core/indexes/base.py", line 3798, in get_loc
    raise KeyError(key) from err
KeyError: 'price'
[2024-05-16T05:27:33.107+0000] {taskinstance.py:1149} INFO - Marking task as FAILED. dag_id=data_pipeline, task_id=analyze_data, execution_date=20240516T052657, start_date=20240516T052732, end_date=20240516T052733
[2024-05-16T05:27:33.128+0000] {standard_task_runner.py:107} ERROR - Failed to execute job 10 for task analyze_data ('price'; 7189)
[2024-05-16T05:27:33.145+0000] {local_task_job_runner.py:234} INFO - Task exited with return code 1
[2024-05-16T05:27:33.170+0000] {taskinstance.py:3312} INFO - 0 downstream tasks scheduled from follow-on schedule check
