[2024-05-16T06:24:30.634+0000] {taskinstance.py:1979} INFO - Dependencies all met for dep_context=non-requeueable deps ti=<TaskInstance: data_pipeline.analyze_data manual__2024-05-16T06:23:55.646278+00:00 [queued]>
[2024-05-16T06:24:30.647+0000] {taskinstance.py:1979} INFO - Dependencies all met for dep_context=requeueable deps ti=<TaskInstance: data_pipeline.analyze_data manual__2024-05-16T06:23:55.646278+00:00 [queued]>
[2024-05-16T06:24:30.648+0000] {taskinstance.py:2193} INFO - Starting attempt 1 of 1
[2024-05-16T06:24:30.671+0000] {taskinstance.py:2217} INFO - Executing <Task(PythonOperator): analyze_data> on 2024-05-16 06:23:55.646278+00:00
[2024-05-16T06:24:30.680+0000] {standard_task_runner.py:60} INFO - Started process 930 to run task
[2024-05-16T06:24:30.683+0000] {standard_task_runner.py:87} INFO - Running: ['***', 'tasks', 'run', 'data_pipeline', 'analyze_data', 'manual__2024-05-16T06:23:55.646278+00:00', '--job-id', '34', '--raw', '--subdir', 'DAGS_FOLDER/pipeline.py', '--cfg-path', '/tmp/tmpkhtu8_li']
[2024-05-16T06:24:30.685+0000] {standard_task_runner.py:88} INFO - Job 34: Subtask analyze_data
[2024-05-16T06:24:30.760+0000] {task_command.py:423} INFO - Running <TaskInstance: data_pipeline.analyze_data manual__2024-05-16T06:23:55.646278+00:00 [running]> on host 07f30c3fd53d
[2024-05-16T06:24:30.861+0000] {taskinstance.py:2513} INFO - Exporting env vars: AIRFLOW_CTX_DAG_OWNER='***' AIRFLOW_CTX_DAG_ID='data_pipeline' AIRFLOW_CTX_TASK_ID='analyze_data' AIRFLOW_CTX_EXECUTION_DATE='2024-05-16T06:23:55.646278+00:00' AIRFLOW_CTX_TRY_NUMBER='1' AIRFLOW_CTX_DAG_RUN_ID='manual__2024-05-16T06:23:55.646278+00:00'
[2024-05-16T06:24:31.018+0000] {taskinstance.py:2731} ERROR - Task failed with exception
Traceback (most recent call last):
  File "/opt/airflow/dags/pipeline.py", line 68, in analyze_data
    sold_prices = properties_df['sold_price']
NameError: name 'properties_df' is not defined

During handling of the above exception, another exception occurred:

Traceback (most recent call last):
  File "/home/airflow/.local/lib/python3.10/site-packages/airflow/models/taskinstance.py", line 444, in _execute_task
    result = _execute_callable(context=context, **execute_callable_kwargs)
  File "/home/airflow/.local/lib/python3.10/site-packages/airflow/models/taskinstance.py", line 414, in _execute_callable
    return execute_callable(context=context, **execute_callable_kwargs)
  File "/home/airflow/.local/lib/python3.10/site-packages/airflow/operators/python.py", line 200, in execute
    return_value = self.execute_callable()
  File "/home/airflow/.local/lib/python3.10/site-packages/airflow/operators/python.py", line 217, in execute_callable
    return self.python_callable(*self.op_args, **self.op_kwargs)
  File "/opt/airflow/dags/pipeline.py", line 103, in analyze_data
    print("Error in analyze_data:", exc_info=True)
TypeError: 'exc_info' is an invalid keyword argument for print()
[2024-05-16T06:24:31.037+0000] {taskinstance.py:1149} INFO - Marking task as FAILED. dag_id=data_pipeline, task_id=analyze_data, execution_date=20240516T062355, start_date=20240516T062430, end_date=20240516T062431
[2024-05-16T06:24:31.057+0000] {standard_task_runner.py:107} ERROR - Failed to execute job 34 for task analyze_data ('exc_info' is an invalid keyword argument for print(); 930)
[2024-05-16T06:24:31.099+0000] {local_task_job_runner.py:234} INFO - Task exited with return code 1
[2024-05-16T06:24:31.125+0000] {taskinstance.py:3312} INFO - 0 downstream tasks scheduled from follow-on schedule check
